<?xml version="1.0" encoding="utf-8"?>
<!-- This URDF was automatically created by SolidWorks to URDF Exporter! Originally created by Stephen Brawner (brawner@gmail.com) 
     Commit Version: 1.6.0-1-g15f4949  Build Version: 1.6.7594.29634
     For more information, please see http://wiki.ros.org/sw_urdf_exporter -->
<robot
  name="argos">

  <gazebo>
    <plugin name="gazebo_ros_control" filename="libgazebo_ros_control.so">
     <robotNamespace>/argos</robotNamespace>
    </plugin>
  </gazebo>


  <link
    name="base_link">
  </link>

  <joint
    name="chassis_joint"
    type="fixed">
    <origin
      xyz="0 0 0"
      rpy="0 0 0" />
    <parent
      link="base_link" />
    <child
      link="chassis_link" />
    <axis
      xyz="0 0 0" />
  </joint>

  <link
    name="chassis_link">
    <inertial>
      <origin
        xyz="0 0 0"
        rpy="0 0 0" />
      <mass
        value="13.494" />
      <inertia
        ixx="1.0864"
        ixy="2.0039E-16"
        ixz="-4.3603E-16"
        iyy="1.3681"
        iyz="-2.8239E-05"
        izz="0.63282" />
    </inertial>
    <visual>
      <origin
        xyz="0 0 0"
        rpy="0 0 0" />
      <geometry>
        <mesh
          filename="package://argos_description/meshes/base_link.STL" />
      </geometry>
      <material
        name="">
        <color
          rgba="0.79216 0.81961 0.93333 1" />
      </material>
    </visual>
    <collision>
      <origin
        xyz="0 0 0"
        rpy="0 0 0" />
      <geometry>
        <mesh
          filename="package://argos_description/meshes/base_link.STL" />
      </geometry>
    </collision>
  </link>

<!-- RIGHT MID WHEEL -->

  <link
    name="right_mid_wheel_link">
    <inertial>
      <origin
        xyz="0 0.015000000000001 0"
        rpy="0 0 0" />
      <mass
        value="0.820122101622573" />
      <inertia
        ixx="0.00342027097529297"
        ixy="-6.3517102092547E-21"
        ixz="4.60785923306339E-19"
        iyy="0.00671792488217426"
        iyz="-1.81154860439012E-19"
        izz="0.00342027097529297" />
    </inertial>
    <visual>
      <origin
        xyz="0 0 0"
        rpy="-1.57 0 0" />
      <geometry>
        <mesh
          filename="package://argos_description/meshes/right_mid_wheel_link.STL" />
      </geometry>
      <material
        name="">
        <color
          rgba="0.792156862745098 0.819607843137255 0.933333333333333 1" />
      </material>
    </visual>
    <collision>
      <origin
        xyz="0 0 0"
        rpy="0 0 0" />
      <geometry>
        <cylinder radius="0.1143" length="0.03"/>
      </geometry>
    </collision>
  </link>
  <joint
    name="right_mid_wheel_joint"
    type="continuous">
    <origin
      xyz="0.21223 0 0"
      rpy="0 -1.57 0" />
    <parent
      link="chassis_link" />
    <child
      link="right_mid_wheel_link" />
    <axis
      xyz="0 0 1" />
  </joint>

<!-- RIGHT REAR WHEEL -->

  <link
    name="right_rear_wheel_link">
    <inertial>
      <origin
        xyz="0 0.0150000000000001 0"
        rpy="0 0 0" />
      <mass
        value="0.820122101622576" />
      <inertia
        ixx="0.00342027097529298"
        ixy="2.01461140192011E-19"
        ixz="1.24683249835833E-18"
        iyy="0.00671792488217428"
        iyz="4.2187156765204E-20"
        izz="0.00342027097529298" />
    </inertial>
    <visual>
      <origin
        xyz="0 0 0"
        rpy="-1.57 0 0" />
      <geometry>
        <mesh
          filename="package://argos_description/meshes/right_rear_wheel_link.STL" />
      </geometry>
      <material
        name="">
        <color
          rgba="0.792156862745098 0.819607843137255 0.933333333333333 1" />
      </material>
    </visual>
    <collision>
      <origin
        xyz="0 0 0"
        rpy="0 0 0" />
      <geometry>
        <cylinder radius="0.1143" length="0.03"/>
      </geometry>
    </collision>
  </link>
  <joint
    name="right_rear_wheel_joint"
    type="continuous">
    <origin
      xyz="0.210 -0.32905 0.00082273"
      rpy="0 -1.57 0" />
    <parent
      link="chassis_link" />
    <child
      link="right_rear_wheel_link" />
    <axis
      xyz="0 0 1" />
  </joint>

<!-- RIGHT FRONT WHEEL -->

  <link
    name="right_front_wheel_link">
    <inertial>
      <origin
        xyz="0 0.015 -6.93889390390723E-18"
        rpy="0 0 0" />
      <mass
        value="0.820122101622575" />
      <inertia
        ixx="0.00342027097529298"
        ixy="6.74204766962017E-20"
        ixz="-3.25260651745651E-19"
        iyy="0.00671792488217427"
        iyz="-2.84377181797463E-19"
        izz="0.00342027097529298" />
    </inertial>
    <visual>
      <origin
        xyz="0 0 0"
        rpy="-1.57 0 0" />
      <geometry>
        <mesh
          filename="package://argos_description/meshes/right_front_wheel_link.STL" />
<!--           <cylinder radius="0.1143" length="0.03"/> -->
      </geometry>
        <material
        name="">
        <color
          rgba="0.792156862745098 0.819607843137255 0.933333333333333 1" />
      </material>
    </visual>
    <collision>
      <origin
        xyz="0 0 0"
        rpy="0 0 0" />
      <geometry>
        <cylinder radius="0.1143" length="0.03"/>
      </geometry>
    </collision>
  </link>
  <joint
    name="right_front_wheel_joint"
    type="continuous">
    <origin
      xyz="0.21223 0.32905 0.00082273"
      rpy="0 -1.57 0" />
    <parent
      link="chassis_link" />
    <child
      link="right_front_wheel_link" />
    <axis
      xyz="0 0 1" />
  </joint>

<!-- LEFT FRONT WHEEL -->

  <link
    name="left_front_wheel_link">
    <inertial>
      <origin
        xyz="0 0.015 1.3878E-17"
        rpy="0 0 0" />
      <mass
        value="0.82012" />
      <inertia
        ixx="0.0034203"
        ixy="2.4819E-20"
        ixz="5.9631E-19"
        iyy="0.0067179"
        iyz="2.8106E-19"
        izz="0.0034203" />
    </inertial>
    <visual>
      <origin
        xyz="0 0 0"
        rpy="-1.57 0 0" />
      <geometry>
        <mesh
          filename="package://argos_description/meshes/left_front_wheel_link.STL" />
<!--           <cylinder radius="0.1143" length="0.03"/> -->
      </geometry>
      <material
        name="">
        <color
          rgba="0.79216 0.81961 0.93333 1" />
      </material>
    </visual>
    <collision>
      <origin
        xyz="0 0 0"
        rpy="0 0 0" />
      <geometry>
        <cylinder radius="0.1143" length="0.03"/>
      </geometry>
    </collision>
  </link>
  <joint
    name="left_front_wheel_joint"
    type="continuous">
    <origin
      xyz="-0.31777 0.32905 0.00082273"
      rpy="0 -1.57 0" />
    <parent
      link="chassis_link" />
    <child
      link="left_front_wheel_link" />
    <axis
      xyz="0 0 1" />
  </joint>

<!-- LEFT REAR WHEEL -->

  <link
    name="left_rear_wheel_link">
    <inertial>
      <origin
        xyz="0 0.015 0"
        rpy="0 0 0" />
      <mass
        value="0.820122101622576" />
      <inertia
        ixx="0.00342027097529298"
        ixy="-2.79214332337302E-19"
        ixz="0"
        iyy="0.00671792488217428"
        iyz="5.55425286818949E-20"
        izz="0.00342027097529298" />
    </inertial>
    <visual>
      <origin
        xyz="0 0 0"
        rpy="-1.57 0 0" />
      <geometry>
        <mesh
          filename="package://argos_description/meshes/left_rear_wheel_link.STL" />
      </geometry>
      <material
        name="">
        <color
          rgba="0.792156862745098 0.819607843137255 0.933333333333333 1" />
      </material>
    </visual>
    <collision>
      <origin
        xyz="0 0 0"
        rpy="0 0 0" />
      <geometry>
        <cylinder radius="0.1143" length="0.03"/>
      </geometry>
    </collision>
  </link>
  <joint
    name="left_rear_wheel_joint"
    type="continuous">
    <origin
      xyz="-0.317 -0.32905 0.00082273"
      rpy="0 -1.57 0" />
    <parent
      link="chassis_link" />
    <child
      link="left_rear_wheel_link" />
    <axis
      xyz="0 0 1" />
  </joint>

<!-- LEFT MID WHEEL -->

  <link
    name="left_mid_wheel_link">
    <inertial>
      <origin
        xyz="0 0.015 0"
        rpy="0 0 0" />
      <mass
        value="0.820122101622574" />
      <inertia
        ixx="0.00342027097529297"
        ixy="5.33859423250119E-20"
        ixz="8.13151629364128E-20"
        iyy="0.00671792488217427"
        iyz="2.05696505401071E-19"
        izz="0.00342027097529297" />
    </inertial>
    <visual>
      <origin
        xyz="0 0 0"
        rpy="-1.57 0 0" />
      <geometry>
        <mesh
          filename="package://argos_description/meshes/left_rear_wheel_link.STL" />
      </geometry>
      <material
        name="">
        <color
          rgba="0.792156862745098 0.819607843137255 0.933333333333333 1" />
      </material>
    </visual>
    <collision>
      <origin
        xyz="0 0 0"
        rpy="0 0 0" />
      <geometry>
        <cylinder radius="0.1143" length="0.03"/>
      </geometry>
    </collision>
  </link>
  <joint
    name="left_mid_wheel_joint"
    type="continuous">
    <origin
      xyz="-0.31777 0 0"
      rpy="0 -1.57 0" />
    <parent
      link="chassis_link" />
    <child
      link="left_mid_wheel_link" />
    <axis
      xyz="0 0 1" />
  </joint>

<!-- MAST -->

  <link
    name="mast_link">
    <inertial>
      <origin
        xyz="0 0 0"
        rpy="0 0 0" />
      <mass
        value="0" />
      <inertia
        ixx="0"
        ixy="0"
        ixz="0"
        iyy="0"
        iyz="0"
        izz="0" />
    </inertial>
    <visual>
      <origin
        xyz="0 0 0"
        rpy="0 0 0" />
      <geometry>
        <mesh
          filename="package://argos_description/meshes/mast_link.STL" />
      </geometry>
      <material
        name="">
        <color
          rgba="1 1 1 1" />
      </material>
    </visual>
    <collision>
      <origin
        xyz="0 0 0"
        rpy="0 0 0" />
      <geometry>
        <mesh
          filename="package://argos_description/meshes/mast_link.STL" />
      </geometry>
    </collision>
  </link>
  <joint
    name="mast_joint"
    type="fixed">
    <origin
      xyz="-0.037765 0.17905 -0.021497"
      rpy="1.5708 0 0" />
    <parent
      link="chassis_link" />
    <child
      link="mast_link" />
    <axis
      xyz="0 0 0" />
  </joint>
  <link
    name="camera_link">
    <inertial>
      <origin
        xyz="0 0.075 2.77555756156289E-17"
        rpy="0 0 0" />
      <mass
        value="6" />
      <inertia
        ixx="0.03125"
        ixy="-7.22801448323669E-19"
        ixz="-1.09865820145197E-19"
        iyy="0.04"
        iyz="-5.42101086242748E-19"
        izz="0.03125" />
    </inertial>
    <visual>
      <origin
        xyz="0 0 0"
        rpy="0 0 0" />
      <geometry>
        <mesh
          filename="package://argos_description/meshes/camera_link.STL" />
      </geometry>
      <material
        name="">
        <color
          rgba="0.792156862745098 0.819607843137255 0.933333333333333 1" />
      </material>
    </visual>
    <collision>
      <origin
        xyz="0 0 0"
        rpy="0 0 0" />
      <geometry>
        <mesh
          filename="package://argos_description/meshes/camera_link.STL" />
      </geometry>
    </collision>
  </link>
  <joint
    name="camera_joint"
    type="fixed">
    <origin
      xyz="0 0.6 0"
      rpy="0 0 0" />
    <parent
      link="mast_link" />
    <child
      link="camera_link" />
    <axis
      xyz="0 0 0" />
  </joint>

  <!--transmissions -->

  <transmission name="left_rear_wheel_trans">
    <type>hardware_interface</type>
    <joint name="left_rear_wheel_joint">
      <hardwareInterface>hardware_interface/VelocityJointInterface</hardwareInterface>
    </joint>
    <actuator name="left_rear_motor">
      <mechanicalReduction>1</mechanicalReduction>
      <motorTorqueConstant>1</motorTorqueConstant>
    </actuator>
  </transmission>
  <transmission name="left_mid_wheel_trans">
    <type>hardware_interface</type>
    <joint name="left_mid_wheel_joint">
      <hardwareInterface>hardware_interface/VelocityJointInterface</hardwareInterface>
    </joint>
    <actuator name="left_mid_motor">
      <mechanicalReduction>1</mechanicalReduction>
      <motorTorqueConstant>1</motorTorqueConstant>
    </actuator>
  </transmission>

  <transmission name="left_front_wheel_trans">
    <type>hardware_interface</type>
    <joint name="left_front_wheel_joint">
      <hardwareInterface>hardware_interface/VelocityJointInterface</hardwareInterface>
    </joint>
    <actuator name="left_front_motor">
      <mechanicalReduction>1</mechanicalReduction>
      <motorTorqueConstant>1</motorTorqueConstant>
    </actuator>
  </transmission>


  <transmission name="right_rear_wheel_trans">
    <type>hardware_interface</type>
    <joint name="right_rear_wheel_joint">
      <hardwareInterface>hardware_interface/VelocityJointInterface</hardwareInterface>
    </joint>
    <actuator name="right_rear_motor">
      <mechanicalReduction>1</mechanicalReduction>
      <motorTorqueConstant>1</motorTorqueConstant>
    </actuator>
  </transmission>
  <transmission name="right_mid_wheel_trans">
    <type>hardware_interface</type>
    <joint name="right_mid_wheel_joint">
      <hardwareInterface>hardware_interface/VelocityJointInterface</hardwareInterface>
    </joint>
    <actuator name="right_mid_motor">
      <mechanicalReduction>1</mechanicalReduction>
      <motorTorqueConstant>1</motorTorqueConstant>
    </actuator>
  </transmission>

  <transmission name="right_front_wheel_trans">
    <type>hardware_interface</type>
    <joint name="right_front_wheel_joint">
      <hardwareInterface>hardware_interface/VelocityJointInterface</hardwareInterface>
    </joint>
    <actuator name="right_front_motor">
      <mechanicalReduction>1</mechanicalReduction>
      <motorTorqueConstant>1</motorTorqueConstant>
    </actuator>
  </transmission>


  <!-- IMU -->
  <joint name="imu_joint" type="fixed">
    <axis xyz="1 0 0"/> <!-- 0 1 0 -->
    <origin xyz="0 0 0.19"/>
    <parent link="base_link"/>
    <child link="imu_link"/>
  </joint>


<link name="imu_link">
  <inertial>
    <mass value="0.001"/>
    <origin rpy="0 0 0" xyz="0 0 0"/>
    <inertia ixx="0.0001" ixy="0" ixz="0" iyy="0.000001" iyz="0" izz="0.0001"/>
  </inertial>
  <visual>
    <origin rpy="0 0 0" xyz="0 0 0"/>
    <geometry>
      <box size="0.001 0.001 0.001"/>
    </geometry>
  </visual>
  <collision>
    <origin rpy="0 0 0" xyz="0 0 0"/>
    <geometry>
      <box size=".001 .001 .001"/>
    </geometry>
  </collision>
</link>


<gazebo reference="imu_link">
  <gravity>true</gravity>
  <sensor name="imu_sensor" type="imu">
    <always_on>true</always_on>
    <update_rate>100</update_rate>
    <visualize>true</visualize>
    <topic>__default_topic__</topic>
    <plugin filename="libgazebo_ros_imu_sensor.so" name="imu_plugin">
      <topicName>imu/data</topicName>
      <bodyName>imu_link</bodyName>
      <updateRateHZ>10.0</updateRateHZ>
      <gaussianNoise>0.0</gaussianNoise>
      <xyzOffset>0 0 0</xyzOffset>
      <rpyOffset>0 0 0</rpyOffset>
      <frameName>base_link</frameName>
      <initialOrientationAsReference>false</initialOrientationAsReference>
    </plugin>
    <pose>0 0 0 0 0 0</pose>
    </sensor>
  </gazebo>

  <!-- Camera -->
<link name="fpv_camera_link">
  <inertial>
    <mass value="0.001"/>
    <origin rpy="0 0 0" xyz="0 0 0"/>
    <inertia ixx="0.0001" ixy="0" ixz="0" iyy="0.000001" iyz="0" izz="0.0001"/>
  </inertial>
  <visual>
    <origin rpy="0 0 0" xyz="0 0 0"/>
    <geometry>
      <box size="0.01 0.01 0.01"/>
    </geometry>
  </visual>
  <collision>
    <origin rpy="0 0 0" xyz="0 0 0"/>
    <geometry>
      <box size=".01 .01 .01"/>
    </geometry>
  </collision>
</link>

  <joint name="fpv_camera_joint" type="fixed">
    <axis xyz="1 0 0"/> <!-- 0 1 0 -->
    <origin xyz="-.03 0.43 0.23" rpy="0 0 1.57"/>
    <parent link="chassis_link"/>
    <child link="fpv_camera_link"/>
  </joint>
  <!-- camera -->
  <gazebo reference="fpv_camera_link">
    <sensor type="camera" name="camera1">
      <update_rate>30.0</update_rate>
      <camera name="head">
        <horizontal_fov>2.70526</horizontal_fov>
        <image>
          <width>700</width>
          <height>400</height>
          <format>R8G8B8</format>
        </image>
        <clip>
          <near>0.02</near>
          <far>300</far>
        </clip>
        <noise>
          <type>gaussian</type>
          <!-- Noise is sampled independently per pixel on each frame.
               That pixel's noise value is added to each of its color
               channels, which at that point lie in the range [0,1]. -->
          <mean>0.0</mean>
          <stddev>0.007</stddev>
        </noise>
      </camera>
      <plugin name="camera_controller" filename="libgazebo_ros_camera.so">
        <alwaysOn>true</alwaysOn>
        <updateRate>0.0</updateRate>
        <cameraName>camera1</cameraName>
        <imageTopicName>image_raw</imageTopicName>
        <cameraInfoTopicName>camera_info</cameraInfoTopicName>
        <frameName>camera_link</frameName>
        <hackBaseline>0.07</hackBaseline>
        <distortionK1>0.0</distortionK1>
        <distortionK2>0.0</distortionK2>
        <distortionK3>0.0</distortionK3>
        <distortionT1>0.0</distortionT1>
        <distortionT2>0.0</distortionT2>
      </plugin>
    </sensor>
  </gazebo>

  <!-- GPS -->
  <link name="navsat_link">
    <visual>
      <geometry>
        <cylinder radius="0.026" length="0.016" />
      </geometry>
      <origin xyz="0 0 0.0" />
      <material name="" />
    </visual>
  </link>
  <joint name="navsat_joint" type="fixed">
    <parent link="chassis_link" />
    <child link="navsat_link" />
    <origin xyz="-0.180 0.126 0.235" />
  </joint>

 <gazebo>
  <plugin name="gps_controller" filename="libhector_gazebo_ros_gps.so">
    <alwayson>true</alwayson>
    <updaterate>1.0</updaterate>
    <bodyname>navsat_link</bodyname>
    <topicname>gps/fix</topicname>
    <frameName>base_link</frameName>
    <frameId>base_link</frameId>
    <velocitytopicname>/fix_velocity</velocitytopicname>
    <drift>0.0 0.0 0.0</drift>
    <gaussiannoise>0.1 0.1 0.1</gaussiannoise>
    <velocitydrift>0 0 0</velocitydrift>
    <velocitygaussiannoise>0.1 0.1 0.1</velocitygaussiannoise>
  </plugin>
 </gazebo>

</robot>