<?xml version="1.0" encoding="utf-8"?>
<!-- This URDF was automatically created by SolidWorks to URDF Exporter! Originally created by Stephen Brawner (brawner@gmail.com) 
     Commit Version: 1.6.0-1-g15f4949  Build Version: 1.6.7594.29634
     For more information, please see http://wiki.ros.org/sw_urdf_exporter -->
<robot
  name="argos">
  <link
    name="base_link">
    <inertial>
      <origin
        xyz="-0.037765 0.10355 0.020925"
        rpy="0 0 0" />
      <mass
        value="13.494" />
      <inertia
        ixx="1.0864"
        ixy="2.0039E-16"
        ixz="-4.3603E-16"
        iyy="1.3681"
        iyz="-2.8239E-05"
        izz="0.63282" />
    </inertial>
    <visual>
      <origin
        xyz="0 0 0"
        rpy="0 0 0" />
      <geometry>
        <mesh
          filename="package://argos_description/meshes/base_link.STL" />
      </geometry>
      <material
        name="">
        <color
          rgba="0.79216 0.81961 0.93333 1" />
      </material>
    </visual>
    <collision>
      <origin
        xyz="0 0 0"
        rpy="0 0 0" />
      <geometry>
        <mesh
          filename="package://argos_description/meshes/base_link.STL" />
      </geometry>
    </collision>
  </link>
  <link
    name="right_rear_motor_link">
    <inertial>
      <origin
        xyz="0 -0.0025 0"
        rpy="0 0 0" />
      <mass
        value="0.021697" />
      <inertia
        ixx="7.8085E-06"
        ixy="-1.916E-22"
        ixz="-4.2352E-22"
        iyy="1.5527E-05"
        iyz="-4.623E-22"
        izz="7.8085E-06" />
    </inertial>
    <visual>
      <origin
        xyz="0 0 0"
        rpy="0 0 0" />
      <geometry>
        <mesh
          filename="package://argos_description/meshes/right_rear_motor_link.STL" />
      </geometry>
      <material
        name="">
        <color
          rgba="0.79216 0.81961 0.93333 1" />
      </material>
    </visual>
    <collision>
      <origin
        xyz="0 0 0"
        rpy="0 0 0" />
      <geometry>
        <mesh
          filename="package://argos_description/meshes/right_rear_motor_link.STL" />
      </geometry>
    </collision>
  </link>
  <joint
    name="right_rear_motor_joint"
    type="fixed">
    <origin
      xyz="0.21723 -0.19595 0.00082273"
      rpy="0 -0.3918 1.5708" />
    <parent
      link="base_link" />
    <child
      link="right_rear_motor_link" />
    <axis
      xyz="0 1 0" />
  </joint>
  <link
    name="right_mid_belt_link">
    <inertial>
      <origin
        xyz="0.0874999999999999 0.00225000000000003 1.95156391047391E-18"
        rpy="0 0 0" />
      <mass
        value="0.00667657609484862" />
      <inertia
        ixx="7.98430672469472E-06"
        ixy="2.48154183765907E-22"
        ixz="9.82121574625244E-21"
        iyy="5.2880412606254E-05"
        iyz="5.205910447834E-22"
        izz="4.49186393258794E-05" />
    </inertial>
    <visual>
      <origin
        xyz="0 0 0"
        rpy="0 0 0" />
      <geometry>
        <mesh
          filename="package://argos_description/meshes/right_mid_belt_link.STL" />
      </geometry>
      <material
        name="">
        <color
          rgba="0.792156862745098 0.819607843137255 0.933333333333333 1" />
      </material>
    </visual>
    <collision>
      <origin
        xyz="0 0 0"
        rpy="0 0 0" />
      <geometry>
        <mesh
          filename="package://argos_description/meshes/right_mid_belt_link.STL" />
      </geometry>
    </collision>
  </link>
  <joint
    name="right_mid_belt_joint"
    type="fixed">
    <origin
      xyz="0.16174 -0.0045 -0.066824"
      rpy="-3.1416 -0.3918 -3.1416" />
    <parent
      link="right_rear_motor_link" />
    <child
      link="right_mid_belt_link" />
    <axis
      xyz="0 0 0" />
  </joint>
  <link
    name="right_mid_gear_link">
    <inertial>
      <origin
        xyz="-1.98408997564847E-17 0.002 -2.32452945780892E-16"
        rpy="0 0 0" />
      <mass
        value="0.0216966242638545" />
      <inertia
        ixx="7.80852466996015E-06"
        ixy="5.02080282874028E-22"
        ixz="0"
        iyy="1.55266467388209E-05"
        iyz="1.16710758237386E-35"
        izz="7.80852466996015E-06" />
    </inertial>
    <visual>
      <origin
        xyz="0 0 0"
        rpy="0 0 0" />
      <geometry>
        <mesh
          filename="package://argos_description/meshes/right_mid_gear_link.STL" />
      </geometry>
      <material
        name="">
        <color
          rgba="0.792156862745098 0.819607843137255 0.933333333333333 1" />
      </material>
    </visual>
    <collision>
      <origin
        xyz="0 0 0"
        rpy="0 0 0" />
      <geometry>
        <mesh
          filename="package://argos_description/meshes/right_mid_gear_link.STL" />
      </geometry>
    </collision>
  </link>
  <joint
    name="right_mid_gear_joint"
    type="continuous">
    <origin
      xyz="0 0 0"
      rpy="3.1416 -1.5708 0" />
    <parent
      link="right_mid_belt_link" />
    <child
      link="right_mid_gear_link" />
    <axis
      xyz="0 1 0" />
  </joint>
  <link
    name="right_mid_wheel_link">
    <inertial>
      <origin
        xyz="2.25514051876985E-16 0.0155000000000001 4.20670442924376E-17"
        rpy="0 0 0" />
      <mass
        value="0.820122101622573" />
      <inertia
        ixx="0.00342027097529297"
        ixy="-6.3517102092547E-21"
        ixz="4.60785923306339E-19"
        iyy="0.00671792488217426"
        iyz="-1.81154860439012E-19"
        izz="0.00342027097529297" />
    </inertial>
    <visual>
      <origin
        xyz="0 0 0"
        rpy="0 0 0" />
      <geometry>
        <mesh
          filename="package://argos_description/meshes/right_mid_wheel_link.STL" />
      </geometry>
      <material
        name="">
        <color
          rgba="0.792156862745098 0.819607843137255 0.933333333333333 1" />
      </material>
    </visual>
    <collision>
      <origin
        xyz="0 0 0"
        rpy="0 0 0" />
      <geometry>
        <mesh
          filename="package://argos_description/meshes/right_mid_wheel_link.STL" />
      </geometry>
    </collision>
  </link>
  <joint
    name="right_mid_wheel_joint"
    type="fixed">
    <origin
      xyz="0 0 0"
      rpy="-3.14159265358979 1.51273617278771 0" />
    <parent
      link="right_mid_gear_link" />
    <child
      link="right_mid_wheel_link" />
    <axis
      xyz="0 0 0" />
  </joint>
  <link
    name="right_rear_belt_link">
    <inertial>
      <origin
        xyz="0.0875 0.00274999999999984 3.58870919092702E-17"
        rpy="0 0 0" />
      <mass
        value="0.00667657609484861" />
      <inertia
        ixx="7.98430672469473E-06"
        ixy="-2.82482179186868E-23"
        ixz="1.77221695884145E-20"
        iyy="5.2880412606254E-05"
        iyz="5.94611613790833E-22"
        izz="4.49186393258794E-05" />
    </inertial>
    <visual>
      <origin
        xyz="0 0 0"
        rpy="0 0 0" />
      <geometry>
        <mesh
          filename="package://argos_description/meshes/right_rear_belt_link.STL" />
      </geometry>
      <material
        name="">
        <color
          rgba="0.792156862745098 0.819607843137255 0.933333333333333 1" />
      </material>
    </visual>
    <collision>
      <origin
        xyz="0 0 0"
        rpy="0 0 0" />
      <geometry>
        <mesh
          filename="package://argos_description/meshes/right_rear_belt_link.STL" />
      </geometry>
    </collision>
  </link>
  <joint
    name="right_rear_belt_joint"
    type="fixed">
    <origin
      xyz="0 0 0"
      rpy="-3.1416 -0.3918 -3.1416" />
    <parent
      link="right_rear_motor_link" />
    <child
      link="right_rear_belt_link" />
    <axis
      xyz="0 0 0" />
  </joint>
  <link
    name="right_rear_gear_link">
    <inertial>
      <origin
        xyz="-1.0842021724855E-19 0.00249999999999975 -5.55111512312578E-17"
        rpy="0 0 0" />
      <mass
        value="0.0216966242638545" />
      <inertia
        ixx="7.80852466996015E-06"
        ixy="-5.02080282874028E-22"
        ixz="-3.74939945665465E-41"
        iyy="1.55266467388209E-05"
        iyz="-2.43906422185256E-57"
        izz="7.80852466996015E-06" />
    </inertial>
    <visual>
      <origin
        xyz="0 0 0"
        rpy="0 0 0" />
      <geometry>
        <mesh
          filename="package://argos_description/meshes/right_rear_gear_link.STL" />
      </geometry>
      <material
        name="">
        <color
          rgba="0.792156862745098 0.819607843137255 0.933333333333333 1" />
      </material>
    </visual>
    <collision>
      <origin
        xyz="0 0 0"
        rpy="0 0 0" />
      <geometry>
        <mesh
          filename="package://argos_description/meshes/right_rear_gear_link.STL" />
      </geometry>
    </collision>
  </link>
  <joint
    name="right_rear_gear_joint"
    type="continuous">
    <origin
      xyz="0.175 0 0"
      rpy="3.14159265358979 -1.5707963267949 0" />
    <parent
      link="right_rear_belt_link" />
    <child
      link="right_rear_gear_link" />
    <axis
      xyz="0 1 0" />
  </joint>
  <link
    name="right_rear_wheel_link">
    <inertial>
      <origin
        xyz="0 0.0200000000000001 0"
        rpy="0 0 0" />
      <mass
        value="0.820122101622576" />
      <inertia
        ixx="0.00342027097529298"
        ixy="2.01461140192011E-19"
        ixz="1.24683249835833E-18"
        iyy="0.00671792488217428"
        iyz="4.2187156765204E-20"
        izz="0.00342027097529298" />
    </inertial>
    <visual>
      <origin
        xyz="0 0 0"
        rpy="0 0 0" />
      <geometry>
        <mesh
          filename="package://argos_description/meshes/right_rear_wheel_link.STL" />
      </geometry>
      <material
        name="">
        <color
          rgba="0.792156862745098 0.819607843137255 0.933333333333333 1" />
      </material>
    </visual>
    <collision>
      <origin
        xyz="0 0 0"
        rpy="0 0 0" />
      <geometry>
        <mesh
          filename="package://argos_description/meshes/right_rear_wheel_link.STL" />
      </geometry>
    </collision>
  </link>
  <joint
    name="right_rear_wheel_joint"
    type="continuous">
    <origin
      xyz="0 0 0"
      rpy="3.14159265358979 -0.17799306621387 0" />
    <parent
      link="right_rear_gear_link" />
    <child
      link="right_rear_wheel_link" />
    <axis
      xyz="0 1 0" />
  </joint>
  <link
    name="right_front_wheel_link">
    <inertial>
      <origin
        xyz="0 0.015 -6.93889390390723E-18"
        rpy="0 0 0" />
      <mass
        value="0.820122101622575" />
      <inertia
        ixx="0.00342027097529298"
        ixy="6.74204766962017E-20"
        ixz="-3.25260651745651E-19"
        iyy="0.00671792488217427"
        iyz="-2.84377181797463E-19"
        izz="0.00342027097529298" />
    </inertial>
    <visual>
      <origin
        xyz="0 0 0"
        rpy="0 0 0" />
      <geometry>
        <mesh
          filename="package://argos_description/meshes/right_front_wheel_link.STL" />
      </geometry>
      <material
        name="">
        <color
          rgba="0.792156862745098 0.819607843137255 0.933333333333333 1" />
      </material>
    </visual>
    <collision>
      <origin
        xyz="0 0 0"
        rpy="0 0 0" />
      <geometry>
        <mesh
          filename="package://argos_description/meshes/right_front_wheel_link.STL" />
      </geometry>
    </collision>
  </link>
  <joint
    name="right_front_wheel_joint"
    type="continuous">
    <origin
      xyz="0.21223 0.32905 0.00082273"
      rpy="0 0.1857 -1.5708" />
    <parent
      link="base_link" />
    <child
      link="right_front_wheel_link" />
    <axis
      xyz="0 1 0" />
  </joint>
  <link
    name="left_front_wheel_link">
    <inertial>
      <origin
        xyz="0 0.015 1.3878E-17"
        rpy="0 0 0" />
      <mass
        value="0.82012" />
      <inertia
        ixx="0.0034203"
        ixy="2.4819E-20"
        ixz="5.9631E-19"
        iyy="0.0067179"
        iyz="2.8106E-19"
        izz="0.0034203" />
    </inertial>
    <visual>
      <origin
        xyz="0 0 0"
        rpy="0 0 0" />
      <geometry>
        <mesh
          filename="package://argos_description/meshes/left_front_wheel_link.STL" />
      </geometry>
      <material
        name="">
        <color
          rgba="0.79216 0.81961 0.93333 1" />
      </material>
    </visual>
    <collision>
      <origin
        xyz="0 0 0"
        rpy="0 0 0" />
      <geometry>
        <mesh
          filename="package://argos_description/meshes/left_front_wheel_link.STL" />
      </geometry>
    </collision>
  </link>
  <joint
    name="left_front_wheel_joint"
    type="continuous">
    <origin
      xyz="-0.28777 0.32905 0.00082273"
      rpy="3.1416 0.1857 -1.5708" />
    <parent
      link="base_link" />
    <child
      link="left_front_wheel_link" />
    <axis
      xyz="0 1 0" />
  </joint>
  <link
    name="left_rear_motor_link">
    <inertial>
      <origin
        xyz="-1.3878E-16 -0.0025 -4.1633E-17"
        rpy="0 0 0" />
      <mass
        value="0.021697" />
      <inertia
        ixx="7.8085E-06"
        ixy="-1.5989E-22"
        ixz="-2.1176E-22"
        iyy="1.5527E-05"
        iyz="3.8844E-22"
        izz="7.8085E-06" />
    </inertial>
    <visual>
      <origin
        xyz="0 0 0"
        rpy="0 0 0" />
      <geometry>
        <mesh
          filename="package://argos_description/meshes/left_rear_motor_link.STL" />
      </geometry>
      <material
        name="">
        <color
          rgba="0.79216 0.81961 0.93333 1" />
      </material>
    </visual>
    <collision>
      <origin
        xyz="0 0 0"
        rpy="0 0 0" />
      <geometry>
        <mesh
          filename="package://argos_description/meshes/left_rear_motor_link.STL" />
      </geometry>
    </collision>
  </link>
  <joint
    name="left_rear_motor_joint"
    type="continuous">
    <origin
      xyz="-0.29277 -0.19595 0.00082273"
      rpy="3.1416 -0.3918 1.5708" />
    <parent
      link="base_link" />
    <child
      link="left_rear_motor_link" />
    <axis
      xyz="0 1 0" />
  </joint>
  <link
    name="left_rear_belt_link">
    <inertial>
      <origin
        xyz="0.0875000000000001 -0.00274999999999992 3.58870919092702E-17"
        rpy="0 0 0" />
      <mass
        value="0.00667657609484862" />
      <inertia
        ixx="7.98430672469472E-06"
        ixy="4.99589517294941E-22"
        ixz="9.72402046718597E-21"
        iyy="5.2880412606254E-05"
        iyz="5.258075508177E-22"
        izz="4.49186393258794E-05" />
    </inertial>
    <visual>
      <origin
        xyz="0 0 0"
        rpy="0 0 0" />
      <geometry>
        <mesh
          filename="package://argos_description/meshes/left_rear_belt_link.STL" />
      </geometry>
      <material
        name="">
        <color
          rgba="0.792156862745098 0.819607843137255 0.933333333333333 1" />
      </material>
    </visual>
    <collision>
      <origin
        xyz="0 0 0"
        rpy="0 0 0" />
      <geometry>
        <mesh
          filename="package://argos_description/meshes/left_rear_belt_link.STL" />
      </geometry>
    </collision>
  </link>
  <joint
    name="left_rear_belt_joint"
    type="fixed">
    <origin
      xyz="0 0 0"
      rpy="0 0.3918 3.1416" />
    <parent
      link="left_rear_motor_link" />
    <child
      link="left_rear_belt_link" />
    <axis
      xyz="0 0 0" />
  </joint>
  <link
    name="left_rear_gear_link">
    <inertial>
      <origin
        xyz="2.16840434497101E-19 0.00249999999999995 5.55111512312578E-17"
        rpy="0 0 0" />
      <mass
        value="0.0216966242638545" />
      <inertia
        ixx="7.80852466996015E-06"
        ixy="5.02080282874028E-22"
        ixz="-3.74939945665465E-41"
        iyy="1.55266467388209E-05"
        iyz="2.43906422185256E-57"
        izz="7.80852466996015E-06" />
    </inertial>
    <visual>
      <origin
        xyz="0 0 0"
        rpy="0 0 0" />
      <geometry>
        <mesh
          filename="package://argos_description/meshes/left_rear_gear_link.STL" />
      </geometry>
      <material
        name="">
        <color
          rgba="0.792156862745098 0.819607843137255 0.933333333333333 1" />
      </material>
    </visual>
    <collision>
      <origin
        xyz="0 0 0"
        rpy="0 0 0" />
      <geometry>
        <mesh
          filename="package://argos_description/meshes/left_rear_gear_link.STL" />
      </geometry>
    </collision>
  </link>
  <joint
    name="left_rear_gear_joint"
    type="continuous">
    <origin
      xyz="0.175 0 0"
      rpy="0 -1.5708 0" />
    <parent
      link="left_rear_belt_link" />
    <child
      link="left_rear_gear_link" />
    <axis
      xyz="0 1 0" />
  </joint>
  <link
    name="left_rear_wheel_link">
    <inertial>
      <origin
        xyz="1.38777878078145E-17 0.0200000000000001 0"
        rpy="0 0 0" />
      <mass
        value="0.820122101622576" />
      <inertia
        ixx="0.00342027097529298"
        ixy="-2.79214332337302E-19"
        ixz="0"
        iyy="0.00671792488217428"
        iyz="5.55425286818949E-20"
        izz="0.00342027097529298" />
    </inertial>
    <visual>
      <origin
        xyz="0 0 0"
        rpy="0 0 0" />
      <geometry>
        <mesh
          filename="package://argos_description/meshes/left_rear_wheel_link.STL" />
      </geometry>
      <material
        name="">
        <color
          rgba="0.792156862745098 0.819607843137255 0.933333333333333 1" />
      </material>
    </visual>
    <collision>
      <origin
        xyz="0 0 0"
        rpy="0 0 0" />
      <geometry>
        <mesh
          filename="package://argos_description/meshes/left_rear_wheel_link.STL" />
      </geometry>
    </collision>
  </link>
  <joint
    name="left_rear_wheel_joint"
    type="continuous">
    <origin
      xyz="0 0 0"
      rpy="3.1416 0.17799 0" />
    <parent
      link="left_rear_gear_link" />
    <child
      link="left_rear_wheel_link" />
    <axis
      xyz="0 1 0" />
  </joint>
  <link
    name="left_mid_belt_link">
    <inertial>
      <origin
        xyz="0.0875 -0.00225 -2.5804E-17"
        rpy="0 0 0" />
      <mass
        value="0.0066766" />
      <inertia
        ixx="7.9843E-06"
        ixy="7.1584E-22"
        ixz="5.3445E-21"
        iyy="5.288E-05"
        iyz="6.0574E-22"
        izz="4.4919E-05" />
    </inertial>
    <visual>
      <origin
        xyz="0 0 0"
        rpy="0 0 0" />
      <geometry>
        <mesh
          filename="package://argos_description/meshes/left_mid_belt_link.STL" />
      </geometry>
      <material
        name="">
        <color
          rgba="0.79216 0.81961 0.93333 1" />
      </material>
    </visual>
    <collision>
      <origin
        xyz="0 0 0"
        rpy="0 0 0" />
      <geometry>
        <mesh
          filename="package://argos_description/meshes/left_mid_belt_link.STL" />
      </geometry>
    </collision>
  </link>
  <joint
    name="left_mid_belt_joint"
    type="fixed">
    <origin
      xyz="0.16174 -0.0045 0.066824"
      rpy="0 0.3918 3.1416" />
    <parent
      link="left_rear_motor_link" />
    <child
      link="left_mid_belt_link" />
    <axis
      xyz="0 0 0" />
  </joint>
  <link
    name="left_mid_gear_link">
    <inertial>
      <origin
        xyz="-1.57209315010398E-17 0.002 1.87350135405495E-16"
        rpy="0 0 0" />
      <mass
        value="0.0216966242638545" />
      <inertia
        ixx="7.80852466996015E-06"
        ixy="1.58992089576735E-20"
        ixz="-3.37037740267766E-34"
        iyy="1.55266467388209E-05"
        iyz="-1.76732259571658E-19"
        izz="7.80852466996015E-06" />
    </inertial>
    <visual>
      <origin
        xyz="0 0 0"
        rpy="0 0 0" />
      <geometry>
        <mesh
          filename="package://argos_description/meshes/left_mid_gear_link.STL" />
      </geometry>
      <material
        name="">
        <color
          rgba="0.792156862745098 0.819607843137255 0.933333333333333 1" />
      </material>
    </visual>
    <collision>
      <origin
        xyz="0 0 0"
        rpy="0 0 0" />
      <geometry>
        <mesh
          filename="package://argos_description/meshes/left_mid_gear_link.STL" />
      </geometry>
    </collision>
  </link>
  <joint
    name="left_mid_gear_joint"
    type="continuous">
    <origin
      xyz="0 0 0"
      rpy="0 -1.5708 0" />
    <parent
      link="left_mid_belt_link" />
    <child
      link="left_mid_gear_link" />
    <axis
      xyz="0 1 0" />
  </joint>
  <link
    name="left_mid_wheel_link">
    <inertial>
      <origin
        xyz="2.15105711021124E-16 0.0155 -2.81892564846231E-17"
        rpy="0 0 0" />
      <mass
        value="0.820122101622574" />
      <inertia
        ixx="0.00342027097529297"
        ixy="5.33859423250119E-20"
        ixz="8.13151629364128E-20"
        iyy="0.00671792488217427"
        iyz="2.05696505401071E-19"
        izz="0.00342027097529297" />
    </inertial>
    <visual>
      <origin
        xyz="0 0 0"
        rpy="0 0 0" />
      <geometry>
        <mesh
          filename="package://argos_description/meshes/left_mid_wheel_link.STL" />
      </geometry>
      <material
        name="">
        <color
          rgba="0.792156862745098 0.819607843137255 0.933333333333333 1" />
      </material>
    </visual>
    <collision>
      <origin
        xyz="0 0 0"
        rpy="0 0 0" />
      <geometry>
        <mesh
          filename="package://argos_description/meshes/left_mid_wheel_link.STL" />
      </geometry>
    </collision>
  </link>
  <joint
    name="left_mid_wheel_joint"
    type="continuous">
    <origin
      xyz="0 0 0"
      rpy="3.1416 -1.5127 0" />
    <parent
      link="left_mid_gear_link" />
    <child
      link="left_mid_wheel_link" />
    <axis
      xyz="0 1 0" />
  </joint>
  <link
    name="mast_link">
    <inertial>
      <origin
        xyz="0 0 0"
        rpy="0 0 0" />
      <mass
        value="0" />
      <inertia
        ixx="0"
        ixy="0"
        ixz="0"
        iyy="0"
        iyz="0"
        izz="0" />
    </inertial>
    <visual>
      <origin
        xyz="0 0 0"
        rpy="0 0 0" />
      <geometry>
        <mesh
          filename="package://argos_description/meshes/mast_link.STL" />
      </geometry>
      <material
        name="">
        <color
          rgba="1 1 1 1" />
      </material>
    </visual>
    <collision>
      <origin
        xyz="0 0 0"
        rpy="0 0 0" />
      <geometry>
        <mesh
          filename="package://argos_description/meshes/mast_link.STL" />
      </geometry>
    </collision>
  </link>
  <joint
    name="mast_joint"
    type="fixed">
    <origin
      xyz="-0.037765 0.17905 -0.021497"
      rpy="1.5708 0 0" />
    <parent
      link="base_link" />
    <child
      link="mast_link" />
    <axis
      xyz="0 0 0" />
  </joint>
  <link
    name="camera_link">
    <inertial>
      <origin
        xyz="0 0.075 2.77555756156289E-17"
        rpy="0 0 0" />
      <mass
        value="6" />
      <inertia
        ixx="0.03125"
        ixy="-7.22801448323669E-19"
        ixz="-1.09865820145197E-19"
        iyy="0.04"
        iyz="-5.42101086242748E-19"
        izz="0.03125" />
    </inertial>
    <visual>
      <origin
        xyz="0 0 0"
        rpy="0 0 0" />
      <geometry>
        <mesh
          filename="package://argos_description/meshes/camera_link.STL" />
      </geometry>
      <material
        name="">
        <color
          rgba="0.792156862745098 0.819607843137255 0.933333333333333 1" />
      </material>
    </visual>
    <collision>
      <origin
        xyz="0 0 0"
        rpy="0 0 0" />
      <geometry>
        <mesh
          filename="package://argos_description/meshes/camera_link.STL" />
      </geometry>
    </collision>
  </link>
  <joint
    name="camera_joint"
    type="fixed">
    <origin
      xyz="0 0.6 0"
      rpy="0 0 0" />
    <parent
      link="mast_link" />
    <child
      link="camera_link" />
    <axis
      xyz="0 0 0" />
  </joint>
</robot>